Workbook

Sheet Лист27
A1: ФИО | B1: e-mail | C1: e-mail МУДЛ | D1: hfccskrf
A2: Гапоненко Сергей Алексеевич | B2: s.a.gaponenko@mtuci.ru | C2: ggserongg@gmail.com | D2: {=_xlfn.XLOOKUP(C2,#REF!,#REF!,0)} -> #REF!
A3: Заликов Руслан Артурович | B3: r.a.zalikov@edu.mtuci.ru | C3: rus.zalikov@bk.ru | D3: {=_xlfn.XLOOKUP(C3,#REF!,#REF!,0)} -> #REF!
A4: Иевлев Кирилл Олегович | B4: k.o.ievlev@mtuci.ru | C4: ievlev.k.o@yandex.ru | D4: {=_xlfn.XLOOKUP(C4,#REF!,#REF!,0)} -> #REF!
A5: Кулагин Владимир Петрович | B5: v.p.kulagin@mtuci.ru | C5: v.p.kulagin@mtuci.ru | D5: {=_xlfn.XLOOKUP(C5,#REF!,#REF!,0)} -> #REF!
A6: Мкртчян Грач Маратович | B6: g.m.mkrtchyan@mtuci.ru | C6: g.m.mkrtchyan@mtuci.ru | D6: {=_xlfn.XLOOKUP(C6,#REF!,#REF!,0)} -> #REF!
A7: Мокин Александр Игоревич | B7: a.i.mokin@mtuci.ru | C7: alejmokin@yandex.ru | D7: {=_xlfn.XLOOKUP(C7,#REF!,#REF!,0)} -> #REF!
A8: Мосева Алеся Сергеевна | B8: a.s.moseva@mtuci.ru | C8: mosevaa@yandex.ru | D8: {=_xlfn.XLOOKUP(C8,#REF!,#REF!,0)} -> #REF!
A9: Мосева Марина Сергеевна | B9: m.s.moseva@mtuci.ru | C9: m.s.moseva@mtuci.ru | D9: {=_xlfn.XLOOKUP(C9,#REF!,#REF!,0)} -> #REF!
A10: Павликов Артем Евгеньевич | B10: a.e.pavlikov@mtuci.ru | C10: a.e.pavlikov@mtuci.ru | D10: {=_xlfn.XLOOKUP(C10,#REF!,#REF!,0)} -> #REF!
A11: Петросян Вера Рафаэловна | B11: v.r.petrosyan@mtuci.ru | C11: v.r.petrosyan@mtuci.ru | D11: {=_xlfn.XLOOKUP(C11,#REF!,#REF!,0)} -> #REF!
A12: Полянцева Ксения Андреевна | B12: k.a.poliantseva@mtuci.ru | C12: k.a.poliantseva@mtuci.ru | D12: {=_xlfn.XLOOKUP(C12,#REF!,#REF!,0)} -> #REF!
A13: Потапченко Тимур Дмитриевич | B13: t.d.potapchenko@mtuci.ru | C13: t.d.potapchenko@mtuci.ru | D13: {=_xlfn.XLOOKUP(C13,#REF!,#REF!,0)} -> #REF!
... A27: Круглов Георгий Николаевич | B27: ronimizy@itmo.ru | C27: ronimizy@niuitmo.ru | D27: {=_xlfn.XLOOKUP(C27,#REF!,#REF!,0)} -> #REF!
A28: Кугаевских Александр Владимирович | B28: avkugaevskikh@itmo.ru | D28: {=_xlfn.XLOOKUP(C28,#REF!,#REF!,0)} -> #REF!
A29: Лимар Иван Александрович | B29: ivan.limar@itmo.ru | C29: ivan.limar@itmo.ru | D29: {=_xlfn.XLOOKUP(C29,#REF!,#REF!,0)} -> #REF!
A30: Ким Станислав Евгеньевич | B30: codeilece@itmo.ru | C30: codeilece@gmail.com | D30: {=_xlfn.XLOOKUP(C30,#REF!,#REF!,0)} -> #REF!
A31: Маркина Татьяна Анатольевна | B31: markina_t@itmo.ru | C31: markina_t@itmo.ru | D31: {=_xlfn.XLOOKUP(C31,#REF!,#REF!,0)} -> #REF!
A32: Москаленко Мария Александровна | B32: mamoskalenko@itmo.ru | C32: moskalenko.mary@gmail.com | D32: {=_xlfn.XLOOKUP(C32,#REF!,#REF!,0)} -> #REF!
A33: Попков Роман Андреевич | B33: rpopkov@itmo.ru | C33: rpopkov@itmo.ru | D33: {=_xlfn.XLOOKUP(C33,#REF!,#REF!,0)} -> #REF!
A34: Правдин Константин Владимирович | B34: kvpravdin@itmo.ru | C34: construeman@gmail.com | D34: {=_xlfn.XLOOKUP(C34,#REF!,#REF!,0)} -> #REF!
A35: Пушкарев Даниил Александрович | B35: dpushkarev@itmo.ru | C35: pushkarevd.89@gmail.com | D35: {=_xlfn.XLOOKUP(C35,#REF!,#REF!,0)} -> #REF!
A36: Свинцов Михаил Викторович | B36: mvsvintsov@itmo.ru | C36: misha.svintsow@gmail.com | D36: {=_xlfn.XLOOKUP(C36,#REF!,#REF!,0)} -> #REF!
A37: Табиева Арина Вадимовна | B37: tabieva.arina@itmo.ru | C37: tabieva.arina@itmo.ru | D37: {=_xlfn.XLOOKUP(C37,#REF!,#REF!,0)} -> #REF!
A38: Трифанов Александр Игоревич | B38: alextrifanov@itmo.ru | C38: alextrifanov@gmail.com | D38: {=_xlfn.XLOOKUP(C38,#REF!,#REF!,0)} -> #REF!
A39: Агарева Ольга Юрьевна | B39: OYAgareva@mephi.ru | C39: oyagareva@mephi.ru | D39: {=_xlfn.XLOOKUP(C39,#REF!,#REF!,0)} -> #REF!
A40: Григорьев Андрей Александрович | B40: AAGrigorev1@mephi.ru | C40: grig.and.al@yandex.ru | D40: {=_xlfn.XLOOKUP(C40,#REF!,#REF!,0)} -> #REF!
... A45: Киреев Василий Сергеевич | B45: VSKireev@mephi.ru | C45: v.kireev1982@gmail.com | D45: {=_xlfn.XLOOKUP(C45,#REF!,#REF!,0)} -> #REF!
A46: Кирова Валерия Орлановна | B46: VOKirova@mephi.ru | D46: {=_xlfn.XLOOKUP(C46,#REF!,#REF!,0)} -> #REF!
A47: Коваленко Александр Евгеньевич | B47: sasha@kovalenko.net.ru | C47: sasha@kovalenko.net.ru | D47: {=_xlfn.XLOOKUP(C47,#REF!,#REF!,0)} -> #REF!
A48: Овчинникова Анастасия Олеговна | B48: AOOvchinnikova@mephi.ru | C48: aoantonova@mail.ru | D48: {=_xlfn.XLOOKUP(C48,#REF!,#REF!,0)} -> #REF!
A49: Рословцев Владимир Владимирович | B49: VVRoslovtsev@mephi.ru | C49: vvroslovtsev@mephi.ru | D49: {=_xlfn.XLOOKUP(C49,#REF!,#REF!,0)} -> #REF!
A50: Смирнов Дмитрий Сергеевич | B50: DSSmirnov@mephi.ru | C50: dvonrims@yandex.ru | D50: {=_xlfn.XLOOKUP(C50,#REF!,#REF!,0)} -> #REF!
A51: Сорока Артем Александрович | B51: AASoroka@mephi.ru | C51: 40aaa@mail.ru | D51: {=_xlfn.XLOOKUP(C51,#REF!,#REF!,0)} -> #REF!
A52: Трофимов Александр Геннадьевич | B52: AGTrofimov@mephi.ru | C52: atrofimov@list.ru | D52: {=_xlfn.XLOOKUP(C52,#REF!,#REF!,0)} -> #REF!
A53: Шильников Кирилл Евгеньевич | B53: KEShilnikov@mephi.ru | C53: shilnikov.k@yandex.ru | D53: {=_xlfn.XLOOKUP(C53,#REF!,#REF!,0)} -> #REF!
A54: Абрамович Александра Юрьевна | B54: ayabramovich@sevsu.ru | C54: ayabramovich@mail.ru | D54: {=_xlfn.XLOOKUP(C54,#REF!,#REF!,0)} -> #REF!
A55: Амосова Светлана Геннадьевна | B55: sgamosova@sevsu.ru | C55: amosovasg@yandex.ru | D55: {=_xlfn.XLOOKUP(C55,#REF!,#REF!,0)} -> #REF!
A56: Безуглая Анна Евгеньевна | B56: aebezuglaya@sevsu.ru | C56: aebezuglaya@sevsu.ru | D56: {=_xlfn.XLOOKUP(C56,#REF!,#REF!,0)} -> #REF!
A57: Бондарев Владимир Николаевич | B57: bondarev@sevsu.ru | C57: bondarev@sevsu.ru | D57: {=_xlfn.XLOOKUP(C57,#REF!,#REF!,0)} -> #REF!
...

Sheet Отказы и замены
A1: a | B1: Наименование направляющей организации | C1: SHORT_NAME | D1: CITY | E1: ФИО | F1: Ф | G1: И | H1: О | I1: ИФ | J1: Должность | K1: Телефон | L1: e-mail | M1: e-mail МУДЛ | N1: Чат | O1: Мудл | P1: Битрикс | Q1: В оф. пис. от 22.06 | R1: Рассылка 22-23 июня | S1: Рассылка про мудл и мах 30.06
A2: =ROW()-1 -> 1 | B2: Федеральное государственное автономное образовательное учреждение высшего образования "Российский университет дружбы народов имени Патриса Лумумбы" | C2: РУДН | D2: Москва | E2: Красиков Виталий Александрович | F2: Красиков | G2: Виталий | H2: Александрович | I2: =G2&" "&F2 -> Виталий Красиков | J2: Доцент кафедры прикладного искусственного интеллекта | K2: 89504211787 | L2: vitkras@inbox.ru | M2: {=_xlfn.XLOOKUP(I2,#REF!,#REF!,"")} -> #REF! | N2: FALSE | O2: =IF(M2="",FALSE,TRUE) -> #REF! | P2: TRUE | Q2: TRUE | R2: TRUE | S2: TRUE | T2: Согласовано с АЦ
A3: 2 | B3: Ордена Трудового Красного Знамени Федеральное государственное бюджетное образовательное учреждение высшего образования "Московский технический университет связи и информатики" | C3: МТУСИ | D3: Санкт-Петербург | E3: Рогов Олег Юрьевич | F3: Рогов | G3: Олег | H3: Юрьевич | I3: =G3&" "&F3 -> Олег Рогов | J3: доцент | K3: =79268976297 -> 79268976297 | L3: o.yu.rogov@mtuci.ru | N3: FALSE | O3: =IF(M3="",FALSE,TRUE) -> FALSE | P3: FALSE | Q3: TRUE | R3: TRUE | S3: FALSE | T3: Согласовано с АЦ
A4: =ROW()-1 -> 3 | B4: Федеральное государственное автономное образовательное учреждение высшего образования "Национальный исследовательский университет ИТМО" | C4: ИТМО | D4: Санкт-Петербург | E4: Лукина Марина Владимировна | F4: Лукина | G4: Марина | H4: Владимировна | I4: =G4&" "&F4 -> Марина Лукина | J4: Преподаватель | K4: 8-921-349-64-04 | L4: mvlukina@itmo.ru | M4: {=_xlfn.XLOOKUP(I4,#REF!,#REF!,"")} -> #REF! | N4: FALSE | O4: =IF(M4="",FALSE,TRUE) -> #REF! | P4: FALSE | Q4: TRUE | R4: TRUE | S4: FALSE | T4: Вместо неё - Ким

Sheet Журнал_conflict1319477655

Sheet Moodle_данные
A1: Синхронизировано | B1: Course ID | C1: Moodle user ID | D1: Moodle ID number | E1: ФИО | F1: Почта | G1: Grade item ID | H1: Элемент оценивания | I1: Тип элемента | J1: Модуль | K1: Минимум | L1: Максимум | M1: Балл | N1: Отображение Moodle | O1: Дата отправки | P1: Дата оценивания
A2: 46230.016 | B2: 12 | C2: 638 | E2: Айсу Бодур | F2: bodur_a@rgau-msha.ru | G2: 181 | H2: Итоговая аттестация | I2: manual | N2: -
A3: 46230.016 | B3: 12 | C3: 638 | E3: Айсу Бодур | F3: bodur_a@rgau-msha.ru | G3: 182 | H3: Кроссвалидация | I3: manual | N3: -
A4: 46230.016 | B4: 12 | C4: 638 | E4: Айсу Бодур | F4: bodur_a@rgau-msha.ru | G4: 174 | H4: Посещение вебинаров | I4: mod | J4: attendance | M4: 100 | N4: 100 | P4: 46209.707
A5: 46230.016 | B5: 12 | C5: 638 | E5: Айсу Бодур | F5: bodur_a@rgau-msha.ru | G5: 180 | H5: Промежуточная аттестация | I5: manual | N5: -
A6: 46230.016 | B6: 12 | C6: 638 | E6: Айсу Бодур | F6: bodur_a@rgau-msha.ru | G6: 175 | H6: Тестирование по модулю 1 | I6: mod | J6: quiz | M6: 75 | N6: 75 | O6: 46216.528 | P6: 46216.528
A7: 46230.016 | B7: 12 | C7: 638 | E7: Айсу Бодур | F7: bodur_a@rgau-msha.ru | G7: 177 | H7: Тестирование по модулю 4 | I7: mod | J7: quiz | N7: -
A8: 46230.016 | B8: 12 | C8: 638 | E8: Айсу Бодур | F8: bodur_a@rgau-msha.ru | G8: 176 | H8: Тестирование по модулям 2 и 3 | I8: mod | J8: quiz | M8: 90 | N8: 90 | O8: 46228.694 | P8: 46228.694
A9: 46230.016 | B9: 12 | C9: 638 | E9: Айсу Бодур | F9: bodur_a@rgau-msha.ru | G9: 168 | H9: Элемент 168 | I9: course | M9: 100 | N9: 100 | P9: 46209.707
A10: 46230.016 | B10: 12 | C10: 747 | D10: 161631 | E10: Александр Багмутов | F10: bagmutov94@mail.ru | G10: 181 | H10: Итоговая аттестация | I10: manual | N10: -
A11: 46230.016 | B11: 12 | C11: 747 | D11: 161631 | E11: Александр Багмутов | F11: bagmutov94@mail.ru | G11: 182 | H11: Кроссвалидация | I11: manual | N11: -
A12: 46230.016 | B12: 12 | C12: 747 | D12: 161631 | E12: Александр Багмутов | F12: bagmutov94@mail.ru | G12: 174 | H12: Посещение вебинаров | I12: mod | J12: attendance | M12: 100 | N12: 100 | P12: 46209.707
A13: 46230.016 | B13: 12 | C13: 747 | D13: 161631 | E13: Александр Багмутов | F13: bagmutov94@mail.ru | G13: 180 | H13: Промежуточная аттестация | I13: manual | N13: -
A14: 46230.016 | B14: 12 | C14: 747 | D14: 161631 | E14: Александр Багмутов | F14: bagmutov94@mail.ru | G14: 175 | H14: Тестирование по модулю 1 | I14: mod | J14: quiz | M14: 100 | N14: 100 | O14: 46216.592 | P14: 46216.592
A15: 46230.016 | B15: 12 | C15: 747 | D15: 161631 | E15: Александр Багмутов | F15: bagmutov94@mail.ru | G15: 177 | H15: Тестирование по модулю 4 | I15: mod | J15: quiz | N15: -
A16: 46230.016 | B16: 12 | C16: 747 | D16: 161631 | E16: Александр Багмутов | F16: bagmutov94@mail.ru | G16: 176 | H16: Тестирование по модулям 2 и 3 | I16: mod | J16: quiz | M16: 95 | N16: 95 | O16: 46227.965 | P16: 46227.965
A17: 46230.016 | B17: 12 | C17: 747 | D17: 161631 | E17: Александр Багмутов | F17: bagmutov94@mail.ru | G17: 168 | H17: Элемент 168 | I17: course | M17: 100 | N17: 100 | P17: 46209.707
A18: 46230.016 | B18: 12 | C18: 758 | E18: Александр Бакулев | F18: contact-bav@mail.ru | G18: 181 | H18: Итоговая аттестация | I18: manual | N18: -
A19: 46230.016 | B19: 12 | C19: 758 | E19: Александр Бакулев | F19: contact-bav@mail.ru | G19: 182 | H19: Кроссвалидация | I19: manual | N19: -
A20: 46230.016 | B20: 12 | C20: 758 | E20: Александр Бакулев | F20: contact-bav@mail.ru | G20: 174 | H20: Посещение вебинаров | I20: mod | J20: attendance | M20: 100 | N20: 100 | P20: 46209.681
A21: 46230.016 | B21: 12 | C21: 758 | E21: Александр Бакулев | F21: contact-bav@mail.ru | G21: 180 | H21: Промежуточная аттестация | I21: manual | N21: -
A22: 46230.016 | B22: 12 | C22: 758 | E22: Александр Бакулев | F22: contact-bav@mail.ru | G22: 175 | H22: Тестирование по модулю 1 | I22: mod | J22: quiz | M22: 87.5 | N22: 87.5 | O22: 46216.347 | P22: 46216.347
A23: 46230.016 | B23: 12 | C23: 758 | E23: Александр Бакулев | F23: contact-bav@mail.ru | G23: 177 | H23: Тестирование по модулю 4 | I23: mod | J23: quiz | N23: -
A24: 46230.016 | B24: 12 | C24: 758 | E24: Александр Бакулев | F24: contact-bav@mail.ru | G24: 176 | H24: Тестирование по модулям 2 и 3 | I24: mod | J24: quiz | M24: 85 | N24: 85 | O24: 46229.966 | P24: 46229.966
A25: 46230.016 | B25: 12 | C25: 758 | E25: Александр Бакулев | F25: contact-bav@mail.ru | G25: 168 | H25: Элемент 168 | I25: course | M25: 100 | N25: 100 | P25: 46209.681
A26: 46230.016 | B26: 12 | C26: 671 | E26: Александр Бастрычкин | F26: a_s_bas@mail.ru | G26: 181 | H26: Итоговая аттестация | I26: manual | N26: -
A27: 46230.016 | B27: 12 | C27: 671 | E27: Александр Бастрычкин | F27: a_s_bas@mail.ru | G27: 182 | H27: Кроссвалидация | I27: manual | N27: -
A28: 46230.016 | B28: 12 | C28: 671 | E28: Александр Бастрычкин | F28: a_s_bas@mail.ru | G28: 174 | H28: Посещение вебинаров | I28: mod | J28: attendance | M28: 100 | N28: 100 | P28: 46211.052
A29: 46230.016 | B29: 12 | C29: 671 | E29: Александр Бастрычкин | F29: a_s_bas@mail.ru | G29: 180 | H29: Промежуточная аттестация | I29: manual | N29: -
A30: 46230.016 | B30: 12 | C30: 671 | E30: Александр Бастрычкин | F30: a_s_bas@mail.ru | G30: 175 | H30: Тестирование по модулю 1 | I30: mod | J30: quiz | M30: 100 | N30: 100 | O30: 46215.831 | P30: 46215.831
A31: 46230.016 | B31: 12 | C31: 671 | E31: Александр Бастрычкин | F31: a_s_bas@mail.ru | G31: 177 | H31: Тестирование по модулю 4 | I31: mod | J31: quiz | N31: -
A32: 46230.016 | B32: 12 | C32: 671 | E32: Александр Бастрычкин | F32: a_s_bas@mail.ru | G32: 176 | H32: Тестирование по модулям 2 и 3 | I32: mod | J32: quiz | M32: 100 | N32: 100 | O32: 46226.406 | P32: 46226.406
A33: 46230.016 | B33: 12 | C33: 671 | E33: Александр Бастрычкин | F33: a_s_bas@mail.ru | G33: 168 | H33: Элемент 168 | I33: course | M33: 100 | N33: 100 | P33: 46211.052
A34: 46230.016 | B34: 12 | C34: 777 | E34: Александр Булычев | F34: bulytchev.isa.ran@gmail.com | G34: 181 | H34: Итоговая аттестация | I34: manual | N34: -
A35: 46230.016 | B35: 12 | C35: 777 | E35: Александр Булычев | F35: bulytchev.isa.ran@gmail.com | G35: 182 | H35: Кроссвалидация | I35: manual | N35: -
A36: 46230.016 | B36: 12 | C36: 777 | E36: Александр Булычев | F36: bulytchev.isa.ran@gmail.com | G36: 174 | H36: Посещение вебинаров | I36: mod | J36: attendance | M36: 100 | N36: 100 | P36: 46209.707
A37: 46230.016 | B37: 12 | C37: 777 | E37: Александр Булычев | F37: bulytchev.isa.ran@gmail.com | G37: 180 | H37: Промежуточная аттестация | I37: manual | N37: -
A38: 46230.016 | B38: 12 | C38: 777 | E38: Александр Булычев | F38: bulytchev.isa.ran@gmail.com | G38: 175 | H38: Тестирование по модулю 1 | I38: mod | J38: quiz | M38: 100 | N38: 100 | O38: 46216.986 | P38: 46216.986
A39: 46230.016 | B39: 12 | C39: 777 | E39: Александр Булычев | F39: bulytchev.isa.ran@gmail.com | G39: 177 | H39: Тестирование по модулю 4 | I39: mod | J39: quiz | N39: -
A40: 46230.016 | B40: 12 | C40: 777 | E40: Александр Булычев | F40: bulytchev.isa.ran@gmail.com | G40: 176 | H40: Тестирование по модулям 2 и 3 | I40: mod | J40: quiz | M40: 90 | N40: 90 | O40: 46229.996 | P40: 46229.996
...

Sheet Входной тест
C1: Полное имя пользователя | E1: Адрес электронной почты | F1: Дата | G1: 1. Какие дисциплины Вы преподаете (или планируете преподавать) по образовательным программам топ-уровня? (Укажите конкретные названия курсов / дисциплин / модулей) | H1: 2. Какой у Вас базовый профиль образования? | I1: 3. Знакомы ли Вы с Компетентностно-ролевой моделью (КРМ) в сфере искусственного интеллекта? | J1: 4. Какие разделы КРМ Вам знакомы лучше всего? *(Выберите все подходящие варианты) | K1: 5. Если на предыдущий вопрс Вы ответили "другое", пожалуйста, поясните | L1: 6. Используете ли Вы КРМ при разработке или актуализации рабочих программ дисциплин (РПД)? | M1: 7. Оцените, насколько Вы умеете "переводить" требования КРМ в конкретные результаты обучения и оценочные средства: | N1: 8. Используете ли Вы КРМ при проектировании фонда оценочных средств (ФОС)? | O1: 9. Оцените от 0 до 4 Ваш практический навык «Проектирование информационных систем без программирования (в том числе с помощью графических языков UML/C4)» | P1: 10. Оцените от 0 до 4 Ваш практический навык «Разработка баз данных (SQL, Ключ-значение, документно-ориентированные…)» | Q1: 11. Оцените от 0 до 4 Ваш практический навык «Python (программирование)» | R1: 12. Оцените от 0 до 4 Ваш практический навык «Работа с библиотеками машинного обучения» | S1: 13. Оцените от 0 до 4 Ваш практический навык «Системы контроля версий (Git)» | T1: 14. Оцените от 0 до 4 Ваш практический навык «Контейнеризация (Docker) и облачные платформы» | U1: 15. Оцените от 0 до 4 Ваш практический навык «Работа с большими данными (обработка, хранение)» | V1: 16. Оцените от 0 до 4 Ваш практический навык «Владение большими языковыми моделями (от общего представления до использования программных интерфейсов)» | W1: 17. Оцените от 0 до 4 Ваш навык «Разработка рабочих программ дисциплин (РПД)» | X1: 18. Оцените от 0 до 4 Ваш навык «Создание фонда оценочных средств (ФОС)» | Y1: 19. Оцените от 0 до 4 Ваш навык «Проектирование практико-ориентированных занятий» | Z1: 20. Оцените от 0 до 4 Ваш навык «Организация проектной и командной работы студентов» | AA1: 21. Оцените от 0 до 4 Ваш навык «Опыт разработки средств автоматизации для учебных целей» | AB1: 22. Оцените от 0 до 4 Ваш опыт участия в совместных проектах с ИТ-компаниями | AC1: 23. Оцените от 0 до 4 вовлечение индустриальных партнеров в учебный процесс на Вашей образовательной программе | AD1: 24. Оцените от 0 до 4 насколько трансформированны реальные бизнес-задачи в Ваши учебные кейсы | AE1: 25. Организовывали ли вы проектную работу студентов? | AF1: 26. Какие роли вы выполняете / готовы выполнять в команде? (Выберите 1-2 основных варианта) | AG1: 27. Какой у вас опыт преподавания (в годах)? | AH1: 28. Каких результатов вы ожидаете от обучения? (Напишите 2-3 ключевых пункта) | AI1: 29. Есть ли у вас конкретные дисциплины / модули, которые вы хотите разработать или актуализировать в рамках проектной работы? Если да, укажите:
A2: TRUE | B2: {=_xlfn.XLOOKUP(E2,#REF!,#REF!)} -> #REF! | C2: Татьяна Синева | E2: t.sineva@g.nsu.ru | F2: 46206.703 | G2: Учебная практика (ознакомительная практика) Введение в проектную деятельность | H2: Информатика / Программирование | I2: Использую КРМ в своей профессиональной деятельности | J2: Компетенции в области машинного обучения (ML) | L2: Планирую начать использовать в ближайшее время | M2: Владею на базовом уровне | N2: Иногда, для отдельных дисциплин | O2: 2 | P2: 2 | Q2: 3 | R2: 2 | S2: 2 | T2: 2 | U2: 2 | V2: 2 | W2: 4 | X2: 4 | Y2: 4 | Z2: 4 | AA2: 3 | AB2: 4 | AC2: 4 | AD2: 3 | AE2: Да, регулярно | AF2: Методолог (проектирование образовательных результатов и ФОС) | AG2: 7–10 лет | AH2: Глубокое понимание КРМ | AI2: Нет
A3: TRUE | B3: {=_xlfn.XLOOKUP(E3,#REF!,#REF!)} -> #REF! | C3: Сергей Кузнецов | E3: sergodk@mail.ru | F3: 46206.71 | G3: Программирование на языке Python | H3: Компьютерные науки | I3: Использую КРМ в своей профессиональной деятельности | J3: Ни один из разделов не знаком | L3: Да, применяю как основу для проектирования | M3: Владею на базовом уровне | N3: Да, для всех дисциплин, которые разрабатываю | O3: 2 | P3: 1 | Q3: 4 | R3: 3 | S3: 4 | T3: 4 | U3: 1 | V3: 2 | W3: 2 | X3: 2 | Y3: 2 | Z3: 3 | AA3: 2 | AB3: 1 | AC3: 2 | AD3: 2 | AE3: Да, регулярно | AF3: Постановщик задач Методолог (проектирование образовательных результатов и ФОС) Практик-разработчик (код, инструменты, инфраструктура) | AG3: Более 10 лет | AH3: Ознакомиться с методологией разработки РПД для программ ТОП_ИИ Понять принципы устройства модели КРМ Научиться разработке актуальных и значимых РПД для программ ТОП_ИИ | AI3: Пока нет.
A4: TRUE | B4: {=_xlfn.XLOOKUP(E4,#REF!,#REF!)} -> #REF! | C4: Михаил Филиппов | E4: m.filippov@g.nsu.ru | F4: 46206.71 | G4: Императивное программирование, Основы ООП, УПРППО. | H4: Математика / Прикладная математика | I4: Слышал(а) о ней, но не изучал(а) подробно | J4: Компетенции в области математических основ ИИ (MF) Компетенции в области машинного обучения (ML) | L4: Нет, никогда не использовал(а) | M4: Владею на базовом уровне | N4: Нет, никогда | O4: 2 | P4: 3 | Q4: 3 | R4: 3 | S4: 3 | T4: 3 | U4: 3 | V4: 3 | W4: 3 | X4: 3 | Y4: 2 | Z4: 3 | AA4: 3 | AB4: 3 | AC4: 2 | AD4: 2 | AE4: Да, регулярно | AF4: Постановщик задач Эксперт по содержанию (глубокое знание предметной области ИИ) Методолог (проектирование образовательных результатов и ФОС) Практик-разработчик (код, инструменты, инфраструктура) Эксперт по КРМ (знание структуры, методик применения) | AG4: 3–6 лет | AH4: Методы обучения, которые вы применяете в своём университете. Организация процессов с бизнесом, как привлечь бизнес надолго. Как эффективно (быстро) сделать методические пособия к предмету. | AI4: Все: Основы ООП, УПРППО, Императивное программирование. Я каждое лето актуализирую.
A5: TRUE | B5: {=_xlfn.XLOOKUP(E5,#REF!,#REF!)} -> #REF! | C5: Irina Dvoretskaya | E5: idorogova@mail.ru | F5: 46206.711 | G5: Теория Вероятностей, прикладной ИИ. | H5: Математика / Прикладная математика | I5: Использую КРМ в своей профессиональной деятельности | J5: Компетенции в области больших языковых моделей (LLM) Компетенции в области жизненного цикла систем искусственного интеллекта (FC) | L5: Планирую начать использовать в ближайшее время | M5: Владею на базовом уровне | N5: Планирую использовать в будущем | O5: 2 | P5: 2 | Q5: 3 | R5: 3 | S5: 2 | T5: 1 | U5: 3 | V5: 2 | W5: 3 | X5: 4 | Y5: 4 | Z5: 4 | AA5: 4 | AB5: 4 | AC5: 4 | AD5: 3 | AE5: Да, регулярно | AF5: Постановщик задач Эксперт по содержанию (глубокое знание предметной области ИИ) Методолог (проектирование образовательных результатов и ФОС) | AG5: 3–6 лет | AH5: 1. Углубить свои знания о КРМ, связать их с знакомыми подходами проектирования обучения 2. Развить навыки постановки задач практического характера с спецификой программы. | AI5: нет
A6: TRUE | B6: {=_xlfn.XLOOKUP(E6,#REF!,#REF!)} -> #REF! | C6: Наталья Исупова | E6: natalyisupova@mail.ru | F6: 46206.712 | G6: Управление ИТ-проектами | H6: Математика / Прикладная математика | I6: Слышал(а) о ней, но не изучал(а) подробно | J6: Компетенции в области математических основ ИИ (MF) | L6: Нет, никогда не использовал(а) | M6: Не владею, не понимаю, как это делать | N6: Нет, никогда | O6: 0 | P6: 2 | Q6: 1 | R6: 0 | S6: 0 | T6: 0 | U6: 0 | V6: 1 | W6: 3 | X6: 3 | Y6: 3 | Z6: 2 | AA6: 1 | AB6: 0 | AC6: 0 | AD6: 1 | AE6: Нет, но планирую | AF6: Методолог (проектирование образовательных результатов и ФОС) | AG6: Более 10 лет | AH6: Прокачка навыков работы с большими данными и ии, крм | AI6: Пока нет
A7: TRUE | B7: {=_xlfn.XLOOKUP(E7,#REF!,#REF!)} -> #REF! | C7: Анастасия Котельникова | E7: usr11503@vyatsu.ru | F7: 46206.712 | G7: Обработка_естественного_языка_и_машинный_анализ_текстов | H7: Информатика / Программирование | I7: Изучал(а) структуру КРМ, но не применял(а) в работе | J7: Компетенции в области машинного обучения (ML) | L7: Да, применяю как основу для проектирования | M7: Владею на базовом уровне | N7: Планирую использовать в будущем | O7: 2 | P7: 1 | Q7: 4 | R7: 3 | S7: 1 | T7: 1 | U7: 2 | V7: 2 | W7: 2 | X7: 2 | Y7: 2 | Z7: 2 | AA7: 2 | AB7: 2 | AC7: 2 | AD7: 2 | AE7: Да, иногда | AF7: Практик-разработчик (код, инструменты, инфраструктура) | AG7: Более 10 лет | AH7: Проще будет оценить позже, когда детальнее узнаю о содержании обучения | AI7: Обработка_естественного_языка_и_машинный_анализ_текстов
A8: TRUE | B8: {=_xlfn.XLOOKUP(E8,#REF!,#REF!)} -> #REF! | C8: Ирина Юманова | E8: yuirfa@mail.ru | F8: 46206.715 | G8: Алгоритмы и методы машинного обучения, машинное обучение | H8: Математика / Прикладная математика | I8: Использую КРМ в своей профессиональной деятельности | J8: Компетенции в области математических основ ИИ (MF) Компетенции в области машинного обучения (ML) | L8: Да, применяю как основу для проектирования | M8: Владею на базовом уровне | N8: Да, для всех дисциплин, которые разрабатываю | O8: 2 | P8: 1 | Q8: 2 | R8: 4 | S8: 2 | T8: 1 | U8: 2 | V8: 2 | W8: 2 | X8: 2 | Y8: 2 | Z8: 2 | AA8: 2 | AB8: 2 | AC8: 3 | AD8: 2 | AE8: Да, иногда | AF8: Методолог (проектирование образовательных результатов и ФОС) | AG8: Более 10 лет | AH8: От обучения я жду прикладных инструментов, которые можно сразу интегрировать в рабочие процессы, а также освоения навыков декомпозиции для грамотной разбивки крупных задач. В совокупности это позволит мне существенно оптимизировать время разработки | AI8: Машинное обучение
A9: TRUE | B9: {=_xlfn.XLOOKUP(E9,#REF!,#REF!)} -> #REF! | C9: Ольга Караваева | E9: karavaeva@vyatsu.ru | F9: 46206.716 | G9: Архитектура операционных систем, Программные комплексы решения интеллектуальных задач. | H9: Компьютерные науки | I9: Слышал(а) о ней, но не изучал(а) подробно | J9: Ни один из разделов не знаком | L9: Планирую начать использовать в ближайшее время | M9: Не владею, не понимаю, как это делать | N9: Планирую использовать в будущем | O9: 2 | P9: 1 | Q9: 1 | R9: 0 | S9: 0 | T9: 0 | U9: 0 | V9: 0 | W9: 2 | X9: 2 | Y9: 1 | Z9: 0 | AA9: 2 | AB9: 0 | AC9: 0 | AD9: 1 | AE9: Нет, не планирую | AF9: Постановщик задач | AG9: Более 10 лет | AH9: Получить навык использования современных технологий в учебном процессе. | AI9: Многопроцессорные операционные системы.
A10: TRUE | B10: {=_xlfn.XLOOKUP(E10,#REF!,#REF!)} -> #REF! | C10: Эльмар Кулиев | E10: elmar_2005@mail.ru | F10: 46206.719 | G10: Архитектуры искусственного интеллекта | H10: Компьютерные науки | I10: Использую КРМ в своей профессиональной деятельности | J10: Компетенции в области машинного обучения (ML) | L10: Да, применяю как основу для проектирования | M10: Владею на базовом уровне | N10: Иногда, для отдельных дисциплин | O10: 1 | P10: 1 | Q10: 0 | R10: 2 | S10: 2 | T10: 0 | U10: 1 | V10: 1 | W10: 3 | X10: 3 | Y10: 3 | Z10: 4 | AA10: 3 | AB10: 3 | AC10: 3 | AD10: 3 | AE10: Да, регулярно | AF10: Постановщик задач Методолог (проектирование образовательных результатов и ФОС) | AG10: 7–10 лет | AH10: Получение навыков, которые можно применить на практике. | AI10: -
A11: TRUE | B11: {=_xlfn.XLOOKUP(E11,#REF!,#REF!)} -> #REF! | C11: Наталья Добровольская | E11: dnu10@mail.ru | F11: 46206.723 | G11: Язык Python, Объектно-ориентированное программирование, Обработка естественного языка | H11: Математика / Прикладная математика | I11: Использую КРМ в своей профессиональной деятельности | J11: Компетенции в области машинного обучения (ML) Компетенции в области больших языковых моделей (LLM) | L11: Да, применяю как основу для проектирования | M11: Владею на базовом уровне | N11: Да, для всех дисциплин, которые разрабатываю | O11: 4 | P11: 1 | Q11: 3 | R11: 1 | S11: 1 | T11: 0 | U11: 1 | V11: 2 | W11: 4 | X11: 4 | Y11: 3 | Z11: 4 | AA11: 4 | AB11: 2 | AC11: 1 | AD11: 1 | AE11: Да, регулярно | AF11: Постановщик задач Методолог (проектирование образовательных результатов и ФОС) | AG11: Более 10 лет | AH11: Приобретение новых навыков разработки ИИ-дисциплин, развитие навыков организации ИИ-проектов | AI11: Акуаоюлизация дисциплины:Обработка естественного языка, разработка модуля ИИ в Java
A12: TRUE | B12: {=_xlfn.XLOOKUP(E12,#REF!,#REF!)} -> #REF! | C12: Арсений Жук | E12: arseniyzhuck@mail.ru | F12: 46206.723 | G12: Технологии компьютерного зрения, Современные методы компьютерного зрения, паттерны проектирования | H12: Математика / Прикладная математика | I12: Использую КРМ в своей профессиональной деятельности | J12: Профессиональные роли Компетенции в области глубокого обучения (DL) | L12: Да, применяю как основу для проектирования | M12: Владею на базовом уровне | N12: Иногда, для отдельных дисциплин | O12: 3 | P12: 3 | Q12: 3 | R12: 3 | S12: 2 | T12: 1 | U12: 1 | V12: 1 | W12: 3 | X12: 3 | Y12: 4 | Z12: 3 | AA12: 3 | AB12: 4 | AC12: 3 | AD12: 3 | AE12: Да, регулярно | AF12: Постановщик задач Эксперт по содержанию (глубокое знание предметной области ИИ) Практик-разработчик (код, инструменты, инфраструктура) | AG12: Более 10 лет | AH12: 1. Повышение навыков использования инструментов обработки больших данных и инструментов работы с ML/DL моделями при проведении лабораторных занятий со студентами 2. Ознакомиться с практиками постановки задач студентам из бизнес-кейсов индустрии, то есть посмотреть, как на практике организовывается работа студентов с реальными задачами индустрии с учетом аспектов доступа, объема задач и времени на погружение, системности построения учебных дисциплин | AI12: 1. Современные методы компьютерного зрения
A13: TRUE | B13: {=_xlfn.XLOOKUP(E13,#REF!,#REF!)} -> #REF! | C13: Евгений Мартюшев | E13: martiushevev@susu.ru | F13: 46206.725 | G13: Математический анализ Специальные главы математики Методы оптимизации | H13: Математика / Прикладная математика | I13: Слышал(а) о ней, но не изучал(а) подробно | J13: Компетенции в области математических основ ИИ (MF) | L13: Нет, никогда не использовал(а) | M13: Не владею, не понимаю, как это делать | N13: Нет, никогда | O13: 0 | P13: 0 | Q13: 1 | R13: 0 | S13: 1 | T13: 0 | U13: 0 | V13: 2 | W13: 2 | X13: 2 | Y13: 0 | Z13: 1 | AA13: 2 | AB13: 1 | AC13: 0 | AD13: 0 | AE13: Нет, не планирую | AF13: Практик-разработчик (код, инструменты, инфраструктура) | AG13: Более 10 лет | AH13: Не знаю | AI13: Нет
... A75: TRUE | B75: {=_xlfn.XLOOKUP(E75,#REF!,#REF!)} -> #REF! | C75: Роман Гараев | E75: demo8916@gmail.com | F75: 46207.543 | G75: -Практическое машинное обучение и глубокое обучение -Обработка естественного языка | H75: Компьютерные науки | I75: Нет, совсем не знаком(а) | J75: Компетенции в области математических основ ИИ (MF) Компетенции в области машинного обучения (ML) Компетенции в области глубокого обучения (DL) Компетенции в области больших языковых моделей (LLM) Компетенции в области жизненного цикла систем искусственного интеллекта (FC) | L75: Нет, никогда не использовал(а) | M75: Не владею, не понимаю, как это делать | N75: Нет, никогда | O75: 1 | P75: 2 | Q75: 4 | R75: 4 | S75: 4 | T75: 4 | U75: 3 | V75: 4 | W75: 1 | X75: 0 | Y75: 3 | Z75: 3 | AA75: 3 | AB75: 4 | AC75: 1 | AD75: 2 | AE75: Да, регулярно | AF75: Постановщик задач Эксперт по содержанию (глубокое знание предметной области ИИ) | AG75: 3–6 лет | AH75: Познакомиться с вашей методологией составления курсов. Пока составление занятий и подача информации основывается на интуиции, опыте, и курсе ISW, интересно изучить более систематизированный подход | AI75: Хочу подготовить элективный курс по безопасным нейронным сетям
A76: TRUE | B76: {=_xlfn.XLOOKUP(E76,#REF!,#REF!)} -> #REF! | C76: Иван Конюхов | E76: i.konyukhov@innopolis.ru | F76: 46207.544 | G76: Математический анализ Аналитическая геометрия Линейная алгебра Дифференциальные уравнения Высокопроизводительные вычисления | H76: Математика / Прикладная математика | I76: Участвовал(а) в разработке или доработке КРМ | J76: Профессиональные роли Компетенции в области математических основ ИИ (MF) Компетенции в области машинного обучения (ML) | K76: Нет | L76: Да, применяю как основу для проектирования | M76: Владею на базовом уровне | N76: Да, для всех дисциплин, которые разрабатываю | O76: 4 | P76: 3 | Q76: 4 | R76: 4 | S76: 4 | T76: 3 | U76: 4 | V76: 4 | W76: 4 | X76: 3 | Y76: 4 | Z76: 4 | AA76: 3 | AB76: 4 | AC76: 3 | AD76: 2 | AE76: Да, регулярно | AF76: Постановщик задач Практик-разработчик (код, инструменты, инфраструктура) | AG76: Более 10 лет | AH76: Интересно посмотреть на автоматизацию создания учебных материалов, фосов с помощью llm, может быть какие-то анкетные истории | AI76: Можно посмотреть на то, как можно было бы трансформировать какую-то классическую дисциплину, вроде математического анализа, под КРМ и вещи, связанные с ИИ. Мы и сами делаем, но, может, что-то упускаем. Интересен взгляд со стороны.
A77: TRUE | B77: {=_xlfn.XLOOKUP(E77,#REF!,#REF!)} -> #REF! | C77: Алексей Забашта | E77: alex.zabashta@yandex.ru | F77: 46207.546 | G77: Автоматическое машинное обучение | H77: Компьютерные науки | I77: Нет, совсем не знаком(а) | J77: Компетенции в области математических основ ИИ (MF) Компетенции в области машинного обучения (ML) Компетенции в области глубокого обучения (DL) Компетенции в области больших языковых моделей (LLM) | L77: Нет, никогда не использовал(а) | M77: Не владею, не понимаю, как это делать | N77: Нет, никогда | O77: 2 | P77: 2 | Q77: 4 | R77: 4 | S77: 3 | T77: 2 | U77: 1 | V77: 4 | W77: 3 | X77: 3 | Y77: 2 | Z77: 4 | AA77: 4 | AB77: 2 | AC77: 4 | AD77: 4 | AE77: Да, иногда | AF77: Постановщик задач Эксперт по содержанию (глубокое знание предметной области ИИ) Методолог (проектирование образовательных результатов и ФОС) Практик-разработчик (код, инструменты, инфраструктура) | AG77: 7–10 лет | AH77: Узнать, что такое КРМ и как её применять | AI77: Автоматическое машинное обучение
A78: TRUE | B78: {=_xlfn.XLOOKUP(E78,#REF!,#REF!)} -> #REF! | C78: Алексей Брюховецкий | E78: a.alexir@mail.ru | F78: 46207.549 | G78: Технологии интеллектуальной защиты информации | H78: Математика / Прикладная математика | I78: Использую КРМ в своей профессиональной деятельности | J78: Компетенции в области математических основ ИИ (MF) Компетенции в области машинного обучения (ML) | L78: Да, применяю как основу для проектирования | M78: Владею на базовом уровне | N78: Иногда, для отдельных дисциплин | O78: 3 | P78: 3 | Q78: 1 | R78: 3 | S78: 1 | T78: 1 | U78: 1 | V78: 1 | W78: 3 | X78: 2 | Y78: 2 | Z78: 1 | AA78: 1 | AB78: 1 | AC78: 2 | AD78: 2 | AE78: Нет, но планирую | AF78: Методолог (проектирование образовательных результатов и ФОС) | AG78: Более 10 лет | AH78: Приобрести навыки практической работы | AI78: В будущем планируется курс по обеспечению безопасности БТС в сетях Vanet
A79: TRUE | B79: {=_xlfn.XLOOKUP(E79,#REF!,#REF!)} -> #REF! | C79: Ольга Иванова | E79: onivanova@susu.ru | F79: 46207.563 | G79: 1. Базы данных 2. Базы данных NoSQL 3. Введение в проектную деятельность 4. Программирование на Python 5. Проектирование человеко-машинного интерфейса 6. Сбор, анализ и предобработка данных в машинном обучении 7. Трек индустриального партнера 8. Учебная практика 9. Машинное обучение 10. Основы DevOps 11. Современные языки программирования высокого уровня 12. Тестирование программного обеспечения 13. Функциональное и логическое программирование 14. Экспертные системы 15. Программная инженерия | H79: Информатика / Программирование | I79: Участвовал(а) в разработке или доработке КРМ | J79: Профессиональные роли Компетенции в области машинного обучения (ML) Компетенции в области глубокого обучения (DL) Компетенции в области жизненного цикла систем искусственного интеллекта (FC) | L79: Да, применяю как основу для проектирования | M79: Владею хорошо, могу обучить коллег | N79: Да, для всех дисциплин, которые разрабатываю | O79: 4 | P79: 4 | Q79: 4 | R79: 4 | S79: 4 | T79: 4 | U79: 4 | V79: 4 | W79: 3 | X79: 3 | Y79: 3 | Z79: 3 | AA79: 3 | AB79: 4 | AC79: 4 | AD79: 3 | AE79: Да, регулярно | AF79: Методолог (проектирование образовательных результатов и ФОС) Эксперт по КРМ (знание структуры, методик применения) | AG79: Более 10 лет | AH79: Я хотела бы актуализировать учебно-методический комплект (рабочую программу, ФОСы, методические материалы и т.д.) по одной из дисциплин таким образом, чтобы она не только соответствовала передовым российским и мировым научным достижениям, но и стала бы целостной образовательной системой от целей и результатов обучения до практических заданий, критериев оценивания, цифровой среды, проектной работы и регулярного обновления содержания с прозрачными, прослеживаемыми результатами освоения компетенций; а также чтобы такая система была адаптирована под новый портрет слушателя - учащийся поколения Z в новых реалиях мира (информационная эра, технологический суверенитет, критические информационные технологии, новые экономические вызовы, ориентация на запрос регионального рынка). | AI79: Если проектная работа будет командная, то я хотела бы актуализировать дисциплину &quot;Сбор, анализ и предобработка данных в машинном обучении&quot;. Если проектная работа будет индивидуальной, то я хотела бы актуализировать дисциплине &quot;Современные языки программирования высокого уровня&quot;
A80: TRUE | B80: {=_xlfn.XLOOKUP(E80,#REF!,#REF!)} -> #REF! | C80: Ирина Сафроненкова | E80: safronenkova050788@yandex.ru | F80: 46207.571 | G80: Представление и использование знаний в интеллектуальных системах Учебная практика | H80: Информатика / Программирование | I80: Слышал(а) о ней, но не изучал(а) подробно | J80: Ни один из разделов не знаком | L80: Нет, никогда не использовал(а) | M80: Не владею, не понимаю, как это делать | N80: Нет, никогда | O80: 1 | P80: 0 | Q80: 1 | R80: 0 | S80: 0 | T80: 0 | U80: 1 | V80: 2 | W80: 2 | X80: 2 | Y80: 2 | Z80: 2 | AA80: 1 | AB80: 0 | AC80: 1 | AD80: 1 | AE80: Да, иногда | AF80: Методолог (проектирование образовательных результатов и ФОС) | AG80: Менее 3 лет | AH80: Усовершенствовать знания в области ИИ | AI80: Представление и использование знаний в интеллектуальных системах
A81: TRUE | B81: {=_xlfn.XLOOKUP(E81,#REF!,#REF!)} -> #REF! | C81: Олег Расин | E81: rasin.oleg@k66.ru | F81: 46207.581 | G81: преподаю: Алгебра и геометрия, Дискретная математика | H81: Математика / Прикладная математика | I81: Слышал(а) о ней, но не изучал(а) подробно | J81: Компетенции в области математических основ ИИ (MF) | L81: Планирую начать использовать в ближайшее время | M81: Владею на базовом уровне | N81: Нет, никогда | O81: 0 | P81: 0 | Q81: 2 | R81: 2 | S81: 1 | T81: 0 | U81: 0 | V81: 1 | W81: 2 | X81: 3 | Y81: 3 | Z81: 3 | AA81: 1 | AB81: 1 | AC81: 3 | AD81: 2 | AE81: Да, иногда | AF81: Методолог (проектирование образовательных результатов и ФОС) | AG81: Более 10 лет | AH81: Познакомиться получше с КРМ Узнать как эффективно использовать в работе | AI81: Хотелось бы предварительно получше понять суть дела
A82: TRUE | B82: {=_xlfn.XLOOKUP(E82,#REF!,#REF!)} -> #REF! | C82: Мария Москаленко | E82: moskalenko.mary@gmail.com | F82: 46207.582 | G82: Линейная алгебра и обработка данных Методы оптимизации Численные методы | H82: Математика / Прикладная математика | I82: Участвовал(а) в разработке или доработке КРМ | J82: Профессиональные роли Компетенции в области математических основ ИИ (MF) Компетенции в области машинного обучения (ML) | L82: Да, применяю как основу для проектирования | M82: Владею хорошо, могу обучить коллег | N82: Да, для всех дисциплин, которые разрабатываю | O82: 2 | P82: 3 | Q82: 2 | R82: 2 | S82: 3 | T82: 1 | U82: 2 | V82: 3 | W82: 4 | X82: 4 | Y82: 3 | Z82: 3 | AA82: 4 | AB82: 2 | AC82: 2 | AD82: 1 | AE82: Да, иногда | AF82: Постановщик задач Методолог (проектирование образовательных результатов и ФОС) Эксперт по КРМ (знание структуры, методик применения) | AG82: Более 10 лет | AH82: Хочу познакомиться со взглядом коллег и экспертов на современное ИИ-образование. | AI82: Теория игр Методы оптимизации
A83: TRUE | B83: {=_xlfn.XLOOKUP(E83,#REF!,#REF!)} -> #REF! | C83: Светлана Турлакова | E83: turlakovasu@susu.ru | F83: 46207.582 | G83: Дискретная математика, Теория вероятностей, Математическая статистика и байесовские модели, Проектно-исследовательский семинар | H83: Математика / Прикладная математика | I83: Использую КРМ в своей профессиональной деятельности | J83: Компетенции в области математических основ ИИ (MF) | L83: Да, применяю как основу для проектирования | M83: Владею на базовом уровне | N83: Да, для всех дисциплин, которые разрабатываю | O83: 0 | P83: 0 | Q83: 2 | R83: 2 | S83: 0 | T83: 0 | U83: 0 | V83: 0 | W83: 4 | X83: 4 | Y83: 4 | Z83: 4 | AA83: 3 | AB83: 1 | AC83: 0 | AD83: 2 | AE83: Нет, но планирую | AF83: Методолог (проектирование образовательных результатов и ФОС) | AG83: Более 10 лет | AH83: Изучить опыт коллег и расширить представление о том, как методически грамотно связывать разделы фундаментальной математики с конкретными механизмами современных нейросетей (трансформеры, диффузионные модели, байесовские подходы) с учетом того, что подробно последние будут изучаться позже на старших курсах. Изучить методический опыт обучения студентов построению полного цикла исследовательского проекта от постановки задачи к реализации простейшего пайплайна, экспериментам с байесовской оптимизацией и получению готового продукта | AI83: Проектно-исследовательский семинар
A84: TRUE | B84: {=_xlfn.XLOOKUP(E84,#REF!,#REF!)} -> #REF! | C84: Александр Трифанов | E84: alextrifanov@gmail.com | F84: 46207.584 | G84: Дифференциальная геометрия, Численные методы линейной алгебры | H84: Математика / Прикладная математика | I84: Использую КРМ в своей профессиональной деятельности | J84: Профессиональные роли Компетенции в области математических основ ИИ (MF) Компетенции в области машинного обучения (ML) | L84: Да, применяю как основу для проектирования | M84: Владею хорошо, могу обучить коллег | N84: Да, для всех дисциплин, которые разрабатываю | O84: 2 | P84: 1 | Q84: 2 | R84: 2 | S84: 3 | T84: 1 | U84: 2 | V84: 3 | W84: 3 | X84: 3 | Y84: 3 | Z84: 3 | AA84: 3 | AB84: 2 | AC84: 2 | AD84: 1 | AE84: Да, иногда | AF84: Постановщик задач Методолог (проектирование образовательных результатов и ФОС) Практик-разработчик (код, инструменты, инфраструктура) | AG84: Более 10 лет | AH84: Получить современные представления об образовании в области ИИ. Практические навыки по проектированию УММ в области ИИ. | AI84: 1. Дифференциальная геометрия 2. Продвинутые методы оптимизации
A85: TRUE | B85: {=_xlfn.XLOOKUP(E85,#REF!,#REF!)} -> #REF! | C85: Светлана Силинская | E85: silinskaya1@mail.ru | F85: 46207.59 | G85: Математические методы и модели исследования операций; Дискретное программирование; Теория вероятностей и математическая статистика; Математический анализ; Функциональный анализ; | H85: Математика / Прикладная математика | I85: Изучал(а) структуру КРМ, но не применял(а) в работе | J85: Профессиональные роли Компетенции в области математических основ ИИ (MF) Компетенции в области машинного обучения (ML) Компетенции в области глубокого обучения (DL) Компетенции в области больших языковых моделей (LLM) | L85: Планирую начать использовать в ближайшее время | M85: Владею на базовом уровне | N85: Иногда, для отдельных дисциплин | O85: 4 | P85: 4 | Q85: 4 | R85: 4 | S85: 4 | T85: 4 | U85: 4 | V85: 4 | W85: 3 | X85: 3 | Y85: 4 | Z85: 3 | AA85: 3 | AB85: 2 | AC85: 2 | AD85: 2 | AE85: Да, регулярно | AF85: Эксперт по содержанию (глубокое знание предметной области ИИ) Практик-разработчик (код, инструменты, инфраструктура) | AG85: Более 10 лет | AH85: Сформировать целостное, системное видение: хочу перейти от фрагментарных знаний об ИИ к стройной картине, чтобы понимать, как логично выстраивать архитектуру образовательных программ. Освоить передовые методики преподавания: научиться объяснять сложные концепции ИИ доступно, но без потери академической или технической глубины. Получить лучшие практики: узнать, как адаптировать учебные материалы под стремительно меняющиеся реалии рынка и технологий. | AI85: Нет
A86: TRUE | B86: {=_xlfn.XLOOKUP(E86,#REF!,#REF!)} -> #REF! | C86: Екатерина Мочалина | E86: mochalina.ep@rea.ru | F86: 46207.594 | G86: Математический анализ, Теория вероятности и математическая статистика, Дискретная математика, Дифференциальные уравнения, Модели временных рядов, | H86: Математика / Прикладная математика | I86: Изучал(а) структуру КРМ, но не применял(а) в работе | J86: Профессиональные роли Компетенции в области математических основ ИИ (MF) | L86: Да, применяю как основу для проектирования | M86: Владею на базовом уровне | N86: Иногда, для отдельных дисциплин | O86: 0 | P86: 0 | Q86: 1 | R86: 1 | S86: 0 | T86: 0 | U86: 1 | V86: 1 | W86: 4 | X86: 4 | Y86: 3 | Z86: 4 | AA86: 2 | AB86: 2 | AC86: 3 | AD86: 1 | AE86: Да, иногда | AF86: Постановщик задач Методолог (проектирование образовательных результатов и ФОС) | AG86: Более 10 лет | AH86: Углубление знаний о КРМ в ИИ, обучение использованию КРМ в работе, идеи проектного обучения с ИИ | AI86: Модели временных рядов и, возможно, остальные тоже
A87: TRUE | B87: {=_xlfn.XLOOKUP(E87,#REF!,#REF!)} -> #REF! | C87: Екатерина Напеденина | E87: napedenina.ey@rea.ru | F87: 46207.594 | G87: Математический анализ, Теория вероятностей и математическая статистика, Дифференциальные уравнения, Дискретная математика, Математическая логика и теория алгоритмов | H87: Математика / Прикладная математика | I87: Изучал(а) структуру КРМ, но не применял(а) в работе | J87: Профессиональные роли Компетенции в области математических основ ИИ (MF) | L87: Планирую начать использовать в ближайшее время | M87: Не владею, не понимаю, как это делать | N87: Планирую использовать в будущем | O87: 0 | P87: 0 | Q87: 1 | R87: 1 | S87: 0 | T87: 0 | U87: 1 | V87: 1 | W87: 4 | X87: 4 | Y87: 1 | Z87: 2 | AA87: 1 | AB87: 2 | AC87: 3 | AD87: 1 | AE87: Да, иногда | AF87: Методолог (проектирование образовательных результатов и ФОС) | AG87: Более 10 лет | AH87: Углубление знаний о КРМ в ИИ, обучение использованию КРМ в преподавательской деятельности, идеи для проектной работы со студентами, использовании ИИ в преподавательской деятельности | AI87: Пока не решила
A88: TRUE | B88: {=_xlfn.XLOOKUP(E88,#REF!,#REF!)} -> #REF! | C88: Ольга Агарева | E88: oyagareva@mephi.ru | F88: 46207.6 | G88: Теория вероятностей и мат. статистика, Случайные процессы, Дифференциальные уравнения и др. | H88: Математика / Прикладная математика | I88: Слышал(а) о ней, но не изучал(а) подробно | J88: Ни один из разделов не знаком | L88: Нет, никогда не использовал(а) | M88: Владею на базовом уровне | N88: Нет, никогда | O88: 0 | P88: 0 | Q88: 0 | R88: 0 | S88: 0 | T88: 0 | U88: 1 | V88: 1 | W88: 3 | X88: 3 | Y88: 3 | Z88: 2 | AA88: 1 | AB88: 0 | AC88: 0 | AD88: 0 | AE88: Нет, не планирую | AF88: Методолог (проектирование образовательных результатов и ФОС) | AG88: Более 10 лет | AH88: Использование ИИ при подготовке к работе | AI88: Нет
... A91: TRUE | B91: {=_xlfn.XLOOKUP(E91,#REF!,#REF!)} -> #REF! | C91: Анна Матохина | E91: matohina.a.v@yandex.ru | F91: 46207.637 | G91: Компьютерная графика, 2D и 3D моделирование, Нарративный геймдизайн | H91: Информатика / Программирование | I91: Изучал(а) структуру КРМ, но не применял(а) в работе | J91: Профессиональные роли Компетенции в области машинного обучения (ML) Компетенции в области больших языковых моделей (LLM) | L91: Да, применяю как основу для проектирования | M91: Владею на базовом уровне | N91: Да, для всех дисциплин, которые разрабатываю | O91: 2 | P91: 3 | Q91: 3 | R91: 2 | S91: 2 | T91: 2 | U91: 2 | V91: 2 | W91: 3 | X91: 3 | Y91: 3 | Z91: 4 | AA91: 3 | AB91: 3 | AC91: 2 | AD91: 2 | AE91: Да, регулярно | AF91: Постановщик задач Эксперт по содержанию (глубокое знание предметной области ИИ) Методолог (проектирование образовательных результатов и ФОС) | AG91: Более 10 лет | AH91: Изучение инструментов для редизайна дисциплин и актуализация содержания с учетом трансформации ролей, новые форматы оценивания и преподавания, варианты решения проблемы поверхностных знаний (вследствие использовании LLM) | AI91: Компьютерная графика, Нарративный геймдизайн
A92: TRUE | B92: {=_xlfn.XLOOKUP(E92,#REF!,#REF!)} -> #REF! | C92: Наталья Паршукова | E92: parshukovanb@susu.ru | F92: 46207.656 | G92: Программирование на Python программирование на C++ Web-программирование для систем искусственного интеллекта Алгоритмы и структуры данных Основы распределенных и облачных вычислений | H92: Информатика / Программирование | I92: Использую КРМ в своей профессиональной деятельности | J92: Профессиональные роли Компетенции в области машинного обучения (ML) Компетенции в области больших языковых моделей (LLM) Другое | K92: компетенции в области программирования и развертывания систем машинного обучения | L92: Да, применяю как основу для проектирования | M92: Владею на базовом уровне | N92: Да, для всех дисциплин, которые разрабатываю | O92: 2 | P92: 4 | Q92: 4 | R92: 2 | S92: 3 | T92: 2 | U92: 3 | V92: 2 | W92: 4 | X92: 4 | Y92: 3 | Z92: 3 | AA92: 3 | AB92: 2 | AC92: 3 | AD92: 3 | AE92: Да, регулярно | AF92: Постановщик задач Практик-разработчик (код, инструменты, инфраструктура) | AG92: Более 10 лет | AH92: освоение новых компетенций в сфере LLM, глубокого обучения, облачных сервисов по работе с ML моделями. обмен опытом с коллегами по организации проектной работы в связке индустриальный партнер - преподаватель - команда студентов | AI92: Web-программирование для систем искусственного интеллекта
A93: TRUE | B93: {=_xlfn.XLOOKUP(E93,#REF!,#REF!)} -> #REF! | C93: Сергей Девятовский | E93: seregadev86@gmail.com | F93: 46207.664 | G93: Линейная алгебра и обработка данных, Математический анализ, методы оптимизации | H93: Математика / Прикладная математика | I93: Слышал(а) о ней, но не изучал(а) подробно | J93: Компетенции в области математических основ ИИ (MF) Компетенции в области машинного обучения (ML) Компетенции в области глубокого обучения (DL) | L93: Планирую начать использовать в ближайшее время | M93: Владею на базовом уровне | N93: Планирую использовать в будущем | O93: 2 | P93: 4 | Q93: 4 | R93: 3 | S93: 3 | T93: 1 | U93: 2 | V93: 3 | W93: 2 | X93: 2 | Y93: 4 | Z93: 3 | AA93: 4 | AB93: 4 | AC93: 3 | AD93: 3 | AE93: Да, иногда | AF93: Постановщик задач Эксперт по содержанию (глубокое знание предметной области ИИ) Методолог (проектирование образовательных результатов и ФОС) Практик-разработчик (код, инструменты, инфраструктура) Эксперт по КРМ (знание структуры, методик применения) | AG93: Менее 3 лет | AH93: Планирую в результате обучения повысить свои компетенции и навыки в области преподавания предметов, связанных с ИИ. | AI93: Пока что затрудняюсь ответить.
A94: TRUE | B94: {=_xlfn.XLOOKUP(E94,#REF!,#REF!)} -> #REF! | C94: Светлана Артемова | E94: seartemova@fa.ru | F94: 46207.676 | G94: Прикладной Data Science в финтехе, Машинное обучение, Технологии обработки данных | H94: Математика / Прикладная математика | I94: Использую КРМ в своей профессиональной деятельности | J94: Профессиональные роли Компетенции в области математических основ ИИ (MF) Компетенции в области машинного обучения (ML) Компетенции в области больших языковых моделей (LLM) Компетенции в области жизненного цикла систем искусственного интеллекта (FC) | L94: Да, применяю как основу для проектирования | M94: Владею хорошо, могу обучить коллег | N94: Да, для всех дисциплин, которые разрабатываю | O94: 4 | P94: 4 | Q94: 4 | R94: 4 | S94: 4 | T94: 4 | U94: 4 | V94: 4 | W94: 4 | X94: 4 | Y94: 4 | Z94: 4 | AA94: 4 | AB94: 4 | AC94: 4 | AD94: 4 | AE94: Да, регулярно | AF94: Постановщик задач Эксперт по содержанию (глубокое знание предметной области ИИ) Методолог (проектирование образовательных результатов и ФОС) Эксперт по КРМ (знание структуры, методик применения) | AG94: Более 10 лет | AH94: Освоить навыки топ-преподавания ИИ Внедрять КРМ в учебный процесс | AI94: Прикладной Data Science Машинное обучение
A95: TRUE | B95: {=_xlfn.XLOOKUP(E95,#REF!,#REF!)} -> #REF! | C95: Никита Гончаров | E95: goncharov.ns.krm@yandex.ru | F95: 46207.681 | G95: Сбор, анализ и предобработка данных в машинном обучении Базы данных Машинное обучение | H95: Математика / Прикладная математика | I95: Слышал(а) о ней, но не изучал(а) подробно | J95: Компетенции в области математических основ ИИ (MF) Компетенции в области машинного обучения (ML) | L95: Планирую начать использовать в ближайшее время | M95: Владею на базовом уровне | N95: Иногда, для отдельных дисциплин | O95: 3 | P95: 4 | Q95: 4 | R95: 3 | S95: 3 | T95: 3 | U95: 3 | V95: 2 | W95: 3 | X95: 2 | Y95: 2 | Z95: 3 | AA95: 2 | AB95: 4 | AC95: 3 | AD95: 2 | AE95: Нет, но планирую | AF95: Постановщик задач | AG95: 3–6 лет | AH95: 1. Хотелось бы ознакомиться с новыми компетенциями при изучении ИИ для студентов. 2. Разобраться с LLM | AI95: Затрудняюсь ответить.
A96: TRUE | B96: {=_xlfn.XLOOKUP(E96,#REF!,#REF!)} -> #REF! | C96: Станислав Драгунов | E96: dragun.se@yandex.ru | F96: 46207.682 | G96: Робототехника Киберфизические системы Системы автоматизированного проектирования Разработка компьютерных игр | H96: Информатика / Программирование | I96: Слышал(а) о ней, но не изучал(а) подробно | J96: Ни один из разделов не знаком | L96: Планирую начать использовать в ближайшее время | M96: Не владею, не понимаю, как это делать | N96: Иногда, для отдельных дисциплин | O96: 3 | P96: 1 | Q96: 2 | R96: 3 | S96: 2 | T96: 2 | U96: 2 | V96: 3 | W96: 4 | X96: 4 | Y96: 4 | Z96: 4 | AA96: 4 | AB96: 3 | AC96: 2 | AD96: 2 | AE96: Да, регулярно | AF96: Постановщик задач Эксперт по содержанию (глубокое знание предметной области ИИ) Методолог (проектирование образовательных результатов и ФОС) Практик-разработчик (код, инструменты, инфраструктура) | AG96: 7–10 лет | AH96: познакомится ближе с КРМ | AI96: Технологии быстрого прототипирование, Разработка игровых механик, технический геймдизайн.
A97: TRUE | B97: {=_xlfn.XLOOKUP(E97,#REF!,#REF!)} -> #REF! | C97: Виталий Кудинов | E97: v.kudinov@g.nsu.ru | F97: 46207.713 | G97: Введение в проектную деятельность | H97: Компьютерные науки | I97: Слышал(а) о ней, но не изучал(а) подробно | J97: Компетенции в области глубокого обучения (DL) | L97: Планирую начать использовать в ближайшее время | M97: Не владею, не понимаю, как это делать | N97: Нет, никогда | O97: 1 | P97: 1 | Q97: 3 | R97: 2 | S97: 3 | T97: 3 | U97: 2 | V97: 2 | W97: 1 | X97: 0 | Y97: 2 | Z97: 2 | AA97: 2 | AB97: 2 | AC97: 2 | AD97: 3 | AE97: Да, регулярно | AF97: Практик-разработчик (код, инструменты, инфраструктура) | AG97: 3–6 лет | AH97: Повышение квалификации и опыта в разработке программ дисциплин | AI97: -
A98: TRUE | B98: {=_xlfn.XLOOKUP(E98,#REF!,#REF!)} -> #REF! | C98: Надежда Могилевская | E98: broshka2011@yandex.ru | F98: 46207.724 | G98: Теория кодирования (сжатие, помехоустойчивое хранение, распределенное отказоустойчивое хранение) Теория автоматов и формальных языков. | H98: Информатика / Программирование | I98: Нет, совсем не знаком(а) | J98: Ни один из разделов не знаком | L98: Нет, никогда не использовал(а) | M98: Не владею, не понимаю, как это делать | N98: Иногда, для отдельных дисциплин | O98: 2 | P98: 1 | Q98: 1 | R98: 0 | S98: 0 | T98: 0 | U98: 2 | V98: 0 | W98: 2 | X98: 2 | Y98: 1 | Z98: 0 | AA98: 1 | AB98: 2 | AC98: 1 | AD98: 0 | AE98: Нет, но планирую | AF98: Методолог (проектирование образовательных результатов и ФОС) Эксперт по КРМ (знание структуры, методик применения) | AG98: Более 10 лет | AH98: Сменить учебные курсы, которые преподаю на более актуальные и востребованные. Хочется проводить занятия по дисциплинам, необходимость знания которых очевидна для студентов. | AI98: нет
A99: TRUE | B99: {=_xlfn.XLOOKUP(E99,#REF!,#REF!)} -> #REF! | C99: Светлана Крошилина | E99: kroshilina_rzn@mail.ru | F99: 46207.742 | G99: Управление проектами в сфере ИИ | H99: Компьютерные науки | I99: Использую КРМ в своей профессиональной деятельности | J99: Профессиональные роли | L99: Да, применяю как основу для проектирования | M99: Владею на базовом уровне | N99: Да, для всех дисциплин, которые разрабатываю | O99: 4 | P99: 4 | Q99: 0 | R99: 0 | S99: 0 | T99: 0 | U99: 0 | V99: 0 | W99: 4 | X99: 4 | Y99: 4 | Z99: 4 | AA99: 4 | AB99: 4 | AC99: 4 | AD99: 4 | AE99: Да, регулярно | AF99: Постановщик задач Методолог (проектирование образовательных результатов и ФОС) | AG99: Более 10 лет | AH99: 1. Структурированный и готовый к применению документ 2. Практическая применимость 3. Гибкость и вариативность | AI99: Управление проектами в сфере ИИ
A100: TRUE | B100: {=_xlfn.XLOOKUP(E100,#REF!,#REF!)} -> #REF! | C100: Садыков Тимур | E100: sadykov.tm@rea.ru | F100: 46207.747 | G100: Преподавал дисциплину &quot;Математический анализ&quot; в 1 семестре. Планирую преподавать дисциплину &quot;Дифференциальные уравнения&quot; в 4 семестре. | H100: Математика / Прикладная математика | I100: Использую КРМ в своей профессиональной деятельности | J100: Компетенции в области математических основ ИИ (MF) | L100: Да, применяю как основу для проектирования | M100: Владею на базовом уровне | N100: Да, для всех дисциплин, которые разрабатываю | O100: 0 | P100: 2 | Q100: 2 | R100: 1 | S100: 1 | T100: 1 | U100: 1 | V100: 1 | W100: 2 | X100: 2 | Y100: 1 | Z100: 1 | AA100: 0 | AB100: 1 | AC100: 4 | AD100: 1 | AE100: Да, иногда | AF100: Методолог (проектирование образовательных результатов и ФОС) | AG100: Более 10 лет | AH100: Овладеть практическими навыками и применить их для создания учебных материалов, которые я смогу применить в ходе преподавания дисциплины &quot;Дифференциальные уравнения&quot; в следующем учебном году. | AI100: Да. Дисциплина &quot;Дифференциальные уравнения&quot;.
A101: TRUE | B101: {=_xlfn.XLOOKUP(E101,#REF!,#REF!)} -> #REF! | C101: Алексей Прутский | E101: prutskiyalex@yandex.ru | F101: 46207.749 | G101: Технологии компьютерного зрения Администрирование информационных сетей ИИ в робототехнике | H101: Математика / Прикладная математика | I101: Использую КРМ в своей профессиональной деятельности | J101: Компетенции в области жизненного цикла систем искусственного интеллекта (FC) | L101: Планирую начать использовать в ближайшее время | M101: Владею на базовом уровне | N101: Иногда, для отдельных дисциплин | O101: 2 | P101: 2 | Q101: 2 | R101: 2 | S101: 3 | T101: 4 | U101: 2 | V101: 2 | W101: 3 | X101: 3 | Y101: 4 | Z101: 4 | AA101: 3 | AB101: 3 | AC101: 3 | AD101: 2 | AE101: Да, регулярно | AF101: Постановщик задач Методолог (проектирование образовательных результатов и ФОС) | AG101: 7–10 лет | AH101: 1 Познакомиться с опытными педагогами 2 Получить опыт в администрировании систем ИИ современных (серверные решения, MLOPS) 3 Научиться применять современные ИИ инструменты в образовании (как применять правильно) | AI101: ИИ в робототехнике
A102: TRUE | B102: {=_xlfn.XLOOKUP(E102,#REF!,#REF!)} -> #REF! | C102: Александр Крошилин | E102: av_kroshilin@mail.ru | F102: 46207.749 | G102: Рекомендательные системы и системы поддержки принятия решений | H102: Компьютерные науки | I102: Использую КРМ в своей профессиональной деятельности | J102: Профессиональные роли | L102: Да, применяю как основу для проектирования | M102: Владею на базовом уровне | N102: Да, для всех дисциплин, которые разрабатываю | O102: 4 | P102: 4 | Q102: 0 | R102: 0 | S102: 0 | T102: 0 | U102: 0 | V102: 0 | W102: 4 | X102: 4 | Y102: 4 | Z102: 4 | AA102: 4 | AB102: 4 | AC102: 4 | AD102: 4 | AE102: Да, регулярно | AF102: Постановщик задач Методолог (проектирование образовательных результатов и ФОС) | AG102: Более 10 лет | AH102: 1. Полная готовность РПД к использованию. 2. Наличие четких критериев оценки и диагностических материалов | AI102: Рекомендательные системы и системы поддержки принятия решений
A103: TRUE | B103: {=_xlfn.XLOOKUP(E103,#REF!,#REF!)} -> #REF! | C103: Владимир Белов | E103: vvbeloff@yandex.ru | F103: 46207.756 | G103: Проектирование интеллектуальных программных систем Математическая статистика для систем искусственного интеллекта | H103: Компьютерные науки | I103: Использую КРМ в своей профессиональной деятельности | J103: Профессиональные роли Компетенции в области математических основ ИИ (MF) | L103: Да, применяю как основу для проектирования | M103: Владею на базовом уровне | N103: Да, для всех дисциплин, которые разрабатываю | O103: 4 | P103: 3 | Q103: 2 | R103: 2 | S103: 1 | T103: 1 | U103: 1 | V103: 1 | W103: 3 | X103: 3 | Y103: 3 | Z103: 2 | AA103: 1 | AB103: 1 | AC103: 1 | AD103: 0 | AE103: Да, регулярно | AF103: Постановщик задач | AG103: Более 10 лет | AH103: 1. Продвижение компетентности в тех позициях, по которым поставил оценку 0, 1 или 2. 2. Увидеть примеры и получить навык трансформации реальных бизнес-задач в учебные кейсы. 3. Углубить навык «Опыт разработки средств автоматизации для учебных целей» | AI103: Проектирование интеллектуальных программных систем Математическая статистика для систем искусственного интеллекта
...

Sheet _Moodle_лог
A1: Время | B1: Статус | C1: Сообщение
A2: 46197.808 | B2: ERROR | C2: Ошибка Moodle: invalidparameter. Сообщение: Обнаружено неверное значение параметра..
A3: 46197.809 | B3: DIAGNOSTIC | C3: Токен принят. Пользователь: Учитель ИТМО; логин: sheets.sync; ID: 586. Ошибка запроса журнала: Ошибка Moodle: invalidparameter. Сообщение: Обнаружено неверное значение параметра..
A4: 46197.812 | B4: OK | C4: Курс: 12; Студентов: 1; Оценочных элементов: 6
A5: 46197.813 | B5: OK | C5: Курс: 12; Студентов: 1; Оценочных элементов: 6
A6: 46197.814 | B6: OK | C6: Курс: 12; Студентов: 1; Оценочных элементов: 6
A7: 46197.834 | B7: OK | C7: Курс: 12; Пользователей: 1; Оценочных элементов: 6
A8: 46197.835 | B8: ERROR | C8: Функция: gradereport_user_get_grade_items. Параметры: {"courseid":"10"}. Ошибка Moodle: requireloginerror. Сообщение: Курс или элемент курса не доступны..
